<mujoco model="schunk_lwa4p">
    <actuator>
        <!-- Physical limits of the actuator. -->
        <motor ctrllimited="true" ctrlrange="-180.0 180.0" joint="arm_1_joint" name="torq_j1"/>
        <motor ctrllimited="true" ctrlrange="-180.0 180.0" joint="arm_2_joint" name="torq_j2"/>
        <motor ctrllimited="true" ctrlrange="-180.0 180.0" joint="arm_3_joint" name="torq_j3"/>
        <motor ctrllimited="true" ctrlrange="-180.0 180.0" joint="arm_4_joint" name="torq_j4"/>
        <motor ctrllimited="true" ctrlrange="-180.0 180.0" joint="arm_5_joint" name="torq_j5"/>
        <motor ctrllimited="true" ctrlrange="-180.0 180.0" joint="arm_6_joint" name="torq_j6"/>
    </actuator>
    <asset>
        <mesh name="arm_base_link" file="meshes/arm_base_link.stl" />
        <mesh name="arm_1_link" file="meshes/arm_1_link.stl" />
        <mesh name="arm_2_link" file="meshes/arm_2_link.stl" />
        <mesh name="arm_3_link" file="meshes/arm_3_link.stl" />
        <mesh name="arm_4_link" file="meshes/arm_4_link.stl" />
        <mesh name="arm_5_link" file="meshes/arm_5_link.stl" />
        <mesh name="arm_6_link" file="meshes/arm_6_link.stl" />
    </asset>
    <worldbody>
        <body name="base" pos="0 0 0">
          <!-- robot view -->
          <camera mode="fixed" name="robotview" pos="1.0 0 0.4" quat="0.653 0.271 0.271 0.653"/>
          <inertial diaginertia="0 0 0" mass="0" pos="0 0 0"/>
          <body name="link0" pos="0 0 0">
            <inertial pos="0 0 0.0" mass="4" diaginertia="0.4 0.4 0.4" />
            <geom pos="0 0 0.052" quat="0 0 1 0" type="mesh" contype="0" conaffinity="0" group="1" mesh="arm_base_link" />
            <geom pos="0 0 0.052" quat="0 0 1 0" type="mesh" mesh="arm_base_link" />
            <body name="arm_1_link" pos="0 0 0.152" quat="0 0 0 1">
                <inertial pos="0 0 0" mass="0.29364" diaginertia="0.01 0.01 0.01" />
                <joint name="arm_1_joint" pos="0 0 0" axis="0 0 1" limited="true" range="-2.947 2.947" damping="0.1"/>
                <geom type="mesh" contype="0" conaffinity="0" group="1" rgba="0 0 0.8 1" mesh="arm_1_link" />
                <geom type="mesh" rgba="0 0 0.8 1" mesh="arm_1_link" />
                <body name="arm_2_link" pos="0 0 0" quat="0.707105 0.707108 0 0">
                    <inertial pos="0 0 0" mass="1.68311" diaginertia="0.03 0.03 0.03" />
                    <joint name="arm_2_joint" pos="0 0 0" axis="0 0 1" limited="true" range="-2.947 2.947" damping="0.1"/>
                    <geom type="mesh" contype="0" conaffinity="0" group="1" rgba="0.7 0.7 0.7 1" mesh="arm_2_link" />
                    <geom type="mesh" rgba="0.7 0.7 0.7 1" mesh="arm_2_link" />
                    <body name="arm_3_link" pos="0 0.35 0" quat="1.32679e-06 0 1 0">
                        <inertial pos="0 0 0" mass="2.1" diaginertia="0.03 0.03 0.03" />
                        <joint name="arm_3_joint" pos="0 0 0" axis="0 0 1" limited="true" range="-2.694 2.694" damping="0.1"/>
                        <geom type="mesh" contype="0" conaffinity="0" group="1" rgba="0 0 0.8 1" mesh="arm_3_link" />
                        <geom type="mesh" rgba="0 0 0.8 1" mesh="arm_3_link" />
                        <body name="arm_4_link" pos="0 0 0" quat="9.38184e-07 -9.38187e-07 0.707105 0.707108">
                            <inertial pos="0 0 0" mass="1.68311" diaginertia="0.03 0.03 0.03" />
                            <joint name="arm_4_joint" pos="0 0 0" axis="0 0 1" limited="true" range="-2.947 2.947" damping="0.1"/>
                            <geom type="mesh" contype="0" conaffinity="0" group="1" rgba="0.7 0.7 0.7 1" mesh="arm_4_link" />
                            <geom type="mesh" rgba="0.7 0.7 0.7 1" mesh="arm_4_link" />
                            <body name="arm_5_link" pos="0 0.005263 0.305" quat="9.38184e-07 9.38187e-07 0.707108 0.707105">
                                <inertial pos="0 0 0" mass="0.807" diaginertia="0.03 0.03 0.03" />
                                <joint name="arm_5_joint" pos="0 0 0" axis="0 0 1" limited="true" range="-2.947 2.947" damping="0.1"/>
                                <geom type="mesh" contype="0" conaffinity="0" group="1" rgba="0 0 0.8 1" mesh="arm_5_link" />
                                <geom type="mesh" rgba="0 0 0.8 1" mesh="arm_5_link" />
                                <body name="arm_6_link" pos="0 0 0" quat="0.707105 -0.707108 0 0">
                                    <inertial pos="0 0 0" mass="0.819" diaginertia="0.01 0.01 0.01" />
                                    <joint name="arm_6_joint" pos="0 0 0" axis="0 0 1" limited="true" range="-2.947 2.947" damping="0.1"/>
                                    <geom type="mesh" contype="0" conaffinity="0" group="1" rgba="0.7 0.7 0.7 1" mesh="arm_6_link" />
                                    <geom type="mesh" rgba="0.7 0.7 0.7 1" mesh="arm_6_link" />
                                    <body name="right_hand" pos="0 0 0.08" quat="0.924 0 0 -0.383">
                                        <inertial pos="0 0 0" mass="0.5" diaginertia="0.05 0.05 0.05" />
                                        <!-- This camera points out from the eef. -->
                                        <camera mode="fixed" name="eye_in_hand" pos="0.05 0 0" quat="0 0.707108 0.707108 0" fovy="75"/>
                                        <!-- to add gripper -->
                                    </body>
                                </body>
                            </body>
                        </body>
                    </body>
                </body>
            </body>
          </body>
        </body>
    </worldbody>
</mujoco>
